2022-11-16 14:39:42,628 INFO    MainThread:2821795 [wandb_setup.py:_flush():68] Configure stats pid to 2821795
2022-11-16 14:39:42,628 INFO    MainThread:2821795 [wandb_setup.py:_flush():68] Loading settings from /home/gsc/.config/wandb/settings
2022-11-16 14:39:42,628 INFO    MainThread:2821795 [wandb_setup.py:_flush():68] Loading settings from /home/gsc/pose_estimation_baseline/2d_to_3d_lifting_baseline/wandb/settings
2022-11-16 14:39:42,628 INFO    MainThread:2821795 [wandb_setup.py:_flush():68] Loading settings from environment variables: {'_require_service': 'True'}
2022-11-16 14:39:42,628 INFO    MainThread:2821795 [wandb_setup.py:_flush():68] Inferring run settings from compute environment: {'program': '<python with no main file>'}
2022-11-16 14:39:42,628 INFO    MainThread:2821795 [wandb_init.py:_log_setup():476] Logging user logs to /home/gsc/pose_estimation_baseline/2d_to_3d_lifting_baseline/wandb/run-20221116_143942-2qoedt2i/logs/debug.log
2022-11-16 14:39:42,628 INFO    MainThread:2821795 [wandb_init.py:_log_setup():477] Logging internal logs to /home/gsc/pose_estimation_baseline/2d_to_3d_lifting_baseline/wandb/run-20221116_143942-2qoedt2i/logs/debug-internal.log
2022-11-16 14:39:42,628 INFO    MainThread:2821795 [wandb_init.py:_jupyter_setup():426] configuring jupyter hooks <wandb.sdk.wandb_init._WandbInit object at 0x7f797532e640>
2022-11-16 14:39:42,628 INFO    MainThread:2821795 [wandb_init.py:init():516] calling init triggers
2022-11-16 14:39:42,628 INFO    MainThread:2821795 [wandb_init.py:init():519] wandb.init called with sweep_config: {}
config: {}
2022-11-16 14:39:42,628 INFO    MainThread:2821795 [wandb_init.py:init():535] re-initializing run, found existing run on stack: 10d1pq7p
2022-11-16 14:39:42,629 INFO    MainThread:2821795 [wandb_run.py:_finish():1746] finishing run kimjunsu/pose_estimation_baseline/10d1pq7p
2022-11-16 14:39:42,629 INFO    MainThread:2821795 [jupyter.py:save_history():448] not saving jupyter history
2022-11-16 14:39:42,629 INFO    MainThread:2821795 [jupyter.py:save_ipynb():378] not saving jupyter notebook
2022-11-16 14:39:42,629 INFO    MainThread:2821795 [wandb_init.py:_jupyter_teardown():408] cleaning up jupyter logic
2022-11-16 14:39:42,660 ERROR   MainThread:2821795 [wandb_init.py:init():1105] error
Traceback (most recent call last):
  File "/home/gsc/anaconda3/envs/baseline/lib/python3.9/site-packages/wandb/sdk/wandb_init.py", line 1078, in init
    run = wi.init()
  File "/home/gsc/anaconda3/envs/baseline/lib/python3.9/site-packages/wandb/sdk/wandb_init.py", line 548, in init
    self._wl._global_run_stack[-1].finish()
  File "/home/gsc/anaconda3/envs/baseline/lib/python3.9/site-packages/wandb/sdk/wandb_run.py", line 292, in wrapper
    return func(self, *args, **kwargs)
  File "/home/gsc/anaconda3/envs/baseline/lib/python3.9/site-packages/wandb/sdk/wandb_run.py", line 255, in wrapper
    return func(self, *args, **kwargs)
  File "/home/gsc/anaconda3/envs/baseline/lib/python3.9/site-packages/wandb/sdk/wandb_run.py", line 1739, in finish
    return self._finish(exit_code, quiet)
  File "/home/gsc/anaconda3/envs/baseline/lib/python3.9/site-packages/wandb/sdk/wandb_run.py", line 1765, in _finish
    manager._inform_finish(run_id=self._run_id)
  File "/home/gsc/anaconda3/envs/baseline/lib/python3.9/site-packages/wandb/sdk/wandb_manager.py", line 183, in _inform_finish
    svc_iface._svc_inform_finish(run_id=run_id)
  File "/home/gsc/anaconda3/envs/baseline/lib/python3.9/site-packages/wandb/sdk/service/service_sock.py", line 54, in _svc_inform_finish
    self._sock_client.send(inform_finish=inform_finish)
  File "/home/gsc/anaconda3/envs/baseline/lib/python3.9/site-packages/wandb/sdk/lib/sock_client.py", line 211, in send
    self.send_server_request(server_req)
  File "/home/gsc/anaconda3/envs/baseline/lib/python3.9/site-packages/wandb/sdk/lib/sock_client.py", line 155, in send_server_request
    self._send_message(msg)
  File "/home/gsc/anaconda3/envs/baseline/lib/python3.9/site-packages/wandb/sdk/lib/sock_client.py", line 152, in _send_message
    self._sendall_with_error_handle(header + data)
  File "/home/gsc/anaconda3/envs/baseline/lib/python3.9/site-packages/wandb/sdk/lib/sock_client.py", line 130, in _sendall_with_error_handle
    sent = self._sock.send(data)
BrokenPipeError: [Errno 32] Broken pipe
